Workbook

Sheet Sheet1
A1: Country | B1: Payment Mode | C1: Currency | D1: TAT | E1: Supported Modes 1 | F1: Supported Modes | G1: Supported Currencies | H1: Network Participant | I1: Channels | J1: Cutoff & delivery timing | K1: Mandatory data requirements | L1: Supporting Documents | M1: Beneficiary Statement Narrative | N1: Proof of Payment | O1: Notes | P1: Transaction limit per end-user - B2B - Min | Q1: Transaction limit per end-user - B2P - Min | R1: Transaction limit per end-user - P2P - Min | S1: Transaction limit per end-user - P2B - Min | T1: Transaction limit per end-user - B2B - Max | U1: Transaction limit per end-user - B2P - Max | V1: Transaction limit per end-user - P2P - Max | W1: Transaction limit per end-user - P2B - Max | X1: Account Verification
A2: Aland Islands | B2: Foreign Currency Wire Transfer (SWIFT) | C2: USD, EUR, SGD, GBP, AUD, CAD, HKD, JPY, CHF, NZD | D2: T1 | E2: B2B, B2P, P2P, P2B | F2: B2B, B2P, P2P, P2B | G2: USD, EUR, SGD, GBP, AUD, CAD, HKD, JPY, CHF, NZD | H2: Bank | I2: All SWIFT enabled banks in the country | J2: Same-day processing subject to cutoff of 07:30 UTC | K2: Remitter Name, Remitter Account Type, Remitter Identification Type, Remitter Identification Number, Remitter Address, Remitter Country Code, Beneficiary Name, Beneficiary Account Type, Beneficiary Account Number, Beneficiary Country Code, Beneficiary Address (Recommended), Beneficiary City (Recommended), Beneficiary Postcode (Recommended), Routing Code Value 1, Routing Code Type 1 - SWIFT Code, Remit Purpose Code | L2: Remitter Beneficiary Relationship, Nature of Business, Duration of Contract, Commercial Agreement, Current Invoice | M2: Remitter Beneficiary Relationship,Nature of Business,Duration of Contract,Commercial Agreement,Current Invoice | N2: MT103 can be considered as a proof of payment and can be provided on request | O2: WIRES can be sent to all countries except for OFAC listed.MT103 can be provided on request.For foreign currency wire currencies USD, EUR, GBP - NIUM supports both OUR and SHA fee type while for other currencies AUD, CAD, CHF, JPY, NZD, HKD, SGD - NIUM supports only SHA fee typeProcessing of payments to Crimea, Donetsk, Luhansk, Sevastopol regions of Ukraine is prohibited. This list is subject to change. | P2: 0 | Q2: 0 | R2: 0 | S2: 0 | T2: No limit | U2: No limit | V2: No limit | W2: No limit
A3: Albania | B3: Bank Account (SEPA) | C3: EUR | D3: Realtime | E3: B2B, B2P, P2P, P2B | F3: B2B, B2P, P2P, P2B | G3: EUR | H3: Bank | I3: All banks connected with SEPA Network | J3: 1. Real-time for transaction amount <= EUR 100,0002. Same-day for transaction amount > EUR 100,000 subject to cutoff of 14.00 EET | K3: Remitter Name, Remitter Account Type, Remitter Address, Remitter Country Code, Remitter Identification Type, Remitter Identification Number, Remit Purpose Code, Remitter City, Remitter Postcode, Beneficiary Name, Beneficiary Country Code, Beneficiary Account Type, Beneficiary Account Number - IBAN, Routing Code Type 1 - SWIFT CODE, Routing Code Value 1 | L3: Remitter Beneficiary Relationship, Nature of Business, Duration of Contract, Commercial Agreement, Current Invoice | M3: Remitter Name & NIUM appears in the beneficiary statement | N3: Upon request, Proof of Payment for a transaction can be made available. | O3: 1. Coverage includes the EU as well as several Non-EU countries.2. Not all supported countries support Realtime payments3. Few banks in Instant supported countries may not support instant payments and payments will be routed through Standard mode in such cases.4.Certain banks require the complete 11-character SWIFT codeâ€”including the branch identifierâ€”in order to accurately route and successfully process the payment. | P3: EUR 0.01 | Q3: EUR 0.01 | R3: EUR 0.01 | S3: EUR 0.01 | T3: No limit | U3: No limit | V3: No limit | W3: No limit
A4: Albania | B4: Foreign Currency Wire Transfer (SWIFT) | C4: USD, EUR, SGD, GBP, AUD, CAD, HKD, JPY, CHF, NZD | D4: T1 | E4: B2B, B2P, P2P, P2B | F4: B2B, B2P, P2P, P2B | G4: USD, EUR, SGD, GBP, AUD, CAD, HKD, JPY, CHF, NZD | H4: Bank | I4: All SWIFT enabled banks in the country | J4: Same-day processing subject to cutoff of 07:30 UTC | K4: Remitter Name, Remitter Account Type, Remitter Identification Type, Remitter Identification Number, Remitter Address, Remitter Country Code, Beneficiary Name, Beneficiary Account Type, Beneficiary Account Number, Beneficiary Country Code, Beneficiary Address, Beneficiary City, Beneficiary Postcode, Routing Code Value 1, Routing Code Type 1 - SWIFT Code, Remit Purpose Code | L4: Remitter Beneficiary Relationship, Nature of Business, Duration of Contract, Commercial Agreement, Current Invoice | M4: Ultimate Sender Name and narrative details will be passed as part of MT103 message to beneficiary bank.Details available on beneficiary statement will be dependent on beneficiary bank. | N4: MT103 can be considered as a proof of payment and can be provided on request | O4: WIRES can be sent to all countries except for OFAC listed.MT103 can be provided on request.NIUM does not support OUR charge type for CAD currency WIRESProcessing of payments to Crimea, Donetsk, Luhansk, Sevastopol regions of Ukraine is prohibited. This list is subject to change. | P4: 0 | Q4: 0 | R4: 0 | S4: 0 | T4: No limit | U4: No limit | V4: No limit | W4: No limit
A5: Albania | B5: Visa Direct | C5: ALL | D5: Realtime | E5: B2B, B2P, P2P, P2B | F5: B2B, B2P, P2P, P2B | G5: ALL | H5: VISA | J5: 1. 24x7 Availability2. Real-time for Fast fund Enabled (Details on fast-fund enabled countries available on request)3. T+2 for other countries | K5: Remitter Name, Remitter Identification Type, Remitter Identification Number, Remitter Country Code, Beneficiary Card Number, Beneficiary Name, Beneficiary Country Code | O5: For more information, please contact your NIUM account manager team. Additional information and approval from VISA is required before this payout method can be made available.Origination of funds is allowed only from a set of countries as mentioned in the table below.In case the transaction currency does not match the destination card issuer currency, amount will be converted and credited in currency of the card issuer.In few countries, only few banks may allow the transactions.Below additional daily/monthly/yearly limits applicable for P2P transactions whichever reached first Per Day - 30 transactions or USD 10,000 per Beneficiary card Per Week - 50 transactions or USD 25,000 per Beneficiary card Per Month - 150 transactions or USD 50,000 per Beneficiary card.Below additional daily/monthly/yearly limits applicable for B2P/B2B transactions whichever reached first Per Day - 30 transactions or USD 50,000 per Beneficiary card Per Week - 50 transactions or USD 100,000 per Beneficiary card Per Month - 150 transactions or USD 200,000 per Beneficiary card. | P5: 0 | Q5: 0 | R5: 0 | S5: 0 | T5: USD 50,000 | U5: USD 50,000 | V5: USD 2,500 | W5: USD 50,000
A6: Algeria | B6: Foreign Currency Wire Transfer (SWIFT) | C6: USD, EUR, SGD, GBP, AUD, CAD, HKD, JPY, CHF, NZD | D6: T1 | E6: B2B, B2P, P2P, P2B | F6: B2B, B2P, P2P, P2B | G6: USD, EUR, SGD, GBP, AUD, CAD, HKD, JPY, CHF, NZD | H6: Bank | I6: All SWIFT enabled banks in the country | J6: Same-day processing subject to cutoff of 07:30 UTC | K6: Remitter Name, Remitter Account Type, Remitter Identification Type, Remitter Identification Number, Remitter Address, Remitter Country Code, Beneficiary Name, Beneficiary Account Type, Beneficiary Account Number, Beneficiary Country Code, Beneficiary Address, Beneficiary City, Beneficiary Postcode, Routing Code Value 1, Routing Code Type 1 - SWIFT Code, Remit Purpose Code | L6: Remitter Beneficiary Relationship, Nature of Business, Duration of Contract, Commercial Agreement, Current Invoice | M6: Ultimate Sender Name and narrative details will be passed as part of MT103 message to beneficiary bank. Details available on beneficiary statement will be dependent on beneficiary bank. | N6: MT103 can be considered as a proof of payment and can be provided on request | O6: WIRES can be sent to all countries except for OFAC listed.MT103 can be provided on request.NIUM does not support OUR charge type for CAD currency WIRESProcessing of payments to Crimea, Donetsk, Luhansk, Sevastopol regions of Ukraine is prohibited. This list is subject to change. | P6: 0 | Q6: 0 | R6: 0 | S6: 0 | T6: No limit | U6: No limit | V6: No limit | W6: No limit
A7: Algeria | B7: Visa Direct | C7: DZD | D7: T2 | E7: B2B, B2P, P2P, P2B | F7: B2B, B2P, P2P, P2B | G7: DZD | H7: VISA | J7: 1. 24x7 Availability2. Real-time for Fast fund Enabled (Details on fast-fund enabled countries available on request)3. T+2 for other countries | K7: Remitter Name, Remitter Identification Type, Remitter Identification Number, Remitter Country Code, Beneficiary Card Number, Beneficiary Name, Beneficiary Country Code | O7: For more information, please contact your NIUM account manager team. Additional information and approval from VISA is required before this payout method can be made available.Origination of funds is allowed only from a set of countries as mentioned in the table below.In case the transaction currency does not match the destination card issuer currency, amount will be converted and credited in currency of the card issuer.In few countries, only few banks may allow the transactions.Below additional daily/monthly/yearly limits applicable for P2P transactions whichever reached first Per Day - 30 transactions or USD 10,000 per Beneficiary card Per Week - 50 transactions or USD 25,000 per Beneficiary card Per Month - 150 transactions or USD 50,000 per Beneficiary card.Below additional daily/monthly/yearly limits applicable for B2P/B2B transactions whichever reached first Per Day - 30 transactions or USD 50,000 per Beneficiary card Per Week - 50 transactions or USD 100,000 per Beneficiary card Per Month - 150 transactions or USD 200,000 per Beneficiary card. | P7: 0 | Q7: 0 | R7: 0 | S7: 0 | T7: USD 50,000 | U7: USD 50,000 | V7: USD 2,500 | W7: USD 50,000
A8: American Samoa | B8: Bank Account (ACH) | C8: USD | D8: T0 | E8: B2B, B2P, P2P, P2B | F8: B2B, B2P, P2P, P2B | G8: USD | H8: Bank | I8: All banks in USA in the ACH network | J8: Same-day day credit subject to cutoff of 15.00 EST | K8: Remitter Name, Remitter Identification Type, Remitter Account Type, Remitter Identification Number, Remitter Country Code, Remitter City, Remitter Address, Remitter State, Remitter Post Code, Remitter Date of Birth (for Individual), Remit Purpose Code, Beneficiary Account Number, Beneficiary Account Type, Beneficiary Name, Routing Code Type 1(ACH Code), Routing Code Value 1, Beneficiary Address, Beneficiary City, Beneficiary Country Code, Beneficiary Post Code, Beneficiary State | L8: Remitter Beneficiary Relationship, Nature of Business, Duration of Contract, Commercial Agreement, Current Invoice | M8: NIUM Transaction ID is passed on and will be visible in the Beneficiaryâ€™s Statement.Remitter Name and statement narrative will be visible in the Beneficiaryâ€™s Account Statement. Clearing system can limit value of each field visible upto 10 characters. | O8: USD ACH payouts can also be done to below countries if the ACH code is supported as per regulator guidelines. - U. S. Virgin Islands , Guam American Samoa , The Northern Mariana Islands.The status update will be done on end of day basis though the Beneficiary may receive the credit before this. | P8: 0 | Q8: 0 | R8: 0 | S8: 0 | T8: USD 1,000,000 | U8: USD 1,000,000 | V8: USD 1,000,000 | W8: USD 1,000,000
A9: American Samoa | B9: Foreign Currency Wire Transfer (SWIFT) | C9: USD, EUR, SGD, GBP, AUD, CAD, HKD, JPY, CHF, NZD | D9: T1 | E9: B2B, B2P, P2P, P2B | F9: B2B, B2P, P2P, P2B | G9: USD, EUR, SGD, GBP, AUD, CAD, HKD, JPY, CHF, NZD | H9: Bank | I9: All SWIFT enabled banks in the country | J9: Same-day processing subject to cutoff of 07:30 UTC | K9: Remitter Name, Remitter Account Type, Remitter Identification Type, Remitter Identification Number, Remitter Address, Remitter Country Code, Beneficiary Name, Beneficiary Account Type, Beneficiary Account Number, Beneficiary Country Code, Beneficiary Address, Beneficiary City, Beneficiary Postcode, Routing Code Value 1, Routing Code Type 1 - SWIFT Code, Remit Purpose Code | L9: Remitter Beneficiary Relationship, Nature of Business, Duration of Contract, Commercial Agreement, Current Invoice | M9: Ultimate Sender Name and narrative details will be passed as part of MT103 message to beneficiary bank.Details available on beneficiary statement will be dependent on beneficiary bank. | N9: MT103 can be considered as a proof of payment and can be provided on request | O9: WIRES can be sent to all countries except for OFAC listed.MT103 can be provided on request.NIUM does not support OUR charge type for CAD currency WIRESProcessing of payments to Crimea, Donetsk, Luhansk, Sevastopol regions of Ukraine is prohibited. This list is subject to change. | P9: 0 | Q9: 0 | R9: 0 | S9: 0 | T9: No limit | U9: No limit | V9: No limit | W9: No limit
A10: Andorra | B10: Bank Account (SEPA) | C10: EUR | D10: Realtime | E10: B2B, B2P, P2P, P2B | F10: B2B, B2P, P2P, P2B | G10: EUR | H10: Bank | I10: All banks connected with SEPA Network | J10: 1. Real-time for transaction amount <= EUR 100,0002. Same-day for transaction amount > EUR 100,000 subject to cutoff of 14.00 EET | K10: Remitter Name, Remitter Account Type, Remitter Address, Remitter Country Code, Remitter Identification Type, Remitter Identification Number, Remit Purpose Code, Remitter City, Remitter Postcode, Beneficiary Name, Beneficiary Country Code, Beneficiary Account Type, Beneficiary Account Number - IBAN, Routing Code Type 1 - SWIFT CODE, Routing Code Value 1 | L10: Remitter Beneficiary Relationship, Nature of Business, Duration of Contract, Commercial Agreement, Current Invoice | M10: Remitter Name & NIUM appears in the beneficiary statement | N10: Upon request, Proof of Payment for a transaction can be made available. | O10: 1. Coverage includes the EU as well as several Non-EU countries.2. Not all supported countries support Realtime payments3. Few banks in Instant supported countries may not support instant payments and payments will be routed through Standard mode in such cases.4.Certain banks require the complete 11-character SWIFT codeâ€”including the branch identifierâ€”in order to accurately route and successfully process the payment. | P10: EUR 0.01 | Q10: EUR 0.01 | R10: EUR 0.01 | S10: EUR 0.01 | T10: No limit | U10: No limit | V10: No limit | W10: No limit
A11: Andorra | B11: Foreign Currency Wire Transfer (SWIFT) | C11: USD, EUR, SGD, GBP, AUD, CAD, HKD, JPY, CHF, NZD | D11: T1 | E11: B2B, B2P, P2P, P2B | F11: B2B, B2P, P2P, P2B | G11: USD, EUR, SGD, GBP, AUD, CAD, HKD, JPY, CHF, NZD | H11: Bank | I11: All SWIFT enabled banks in the country | J11: Same-day processing subject to cutoff of 07:30 UTC | K11: Remitter Name, Remitter Account Type, Remitter Identification Type, Remitter Identification Number, Remitter Address, Remitter Country Code, Beneficiary Name, Beneficiary Account Type, Beneficiary Account Number, Beneficiary Country Code, Beneficiary Address, Beneficiary City, Beneficiary Postcode, Routing Code Value 1, Routing Code Type 1 - SWIFT Code, Remit Purpose Code | L11: Remitter Beneficiary Relationship, Nature of Business, Duration of Contract, Commercial Agreement, Current Invoice | M11: Ultimate Sender Name and narrative details will be passed as part of MT103 message to beneficiary bank.Details available on beneficiary statement will be dependent on beneficiary bank. | N11: MT103 can be considered as a proof of payment and can be provided on request | O11: WIRES can be sent to all countries except for OFAC listed.MT103 can be provided on request.NIUM does not support OUR charge type for CAD currency WIRESProcessing of payments to Crimea, Donetsk, Luhansk, Sevastopol regions of Ukraine is prohibited. This list is subject to change. | P11: 0 | Q11: 0 | R11: 0 | S11: 0 | T11: No limit | U11: No limit | V11: No limit | W11: No limit
A12: Andorra | B12: Visa Direct | C12: EUR | D12: T2 | E12: B2B, B2P, P2P, P2B | F12: B2B, B2P, P2P, P2B | G12: EUR | H12: VISA | J12: 1. 24x7 Availability2. Real-time for Fast fund Enabled (Details on fast-fund enabled countries available on request)3. T+2 for other countries | K12: Remitter Name, Remitter Identification Type, Remitter Identification Number, Remitter Country Code, Beneficiary Card Number, Beneficiary Name, Beneficiary Country Code | O12: For more information, please contact your NIUM account manager team. Additional information and approval from VISA is required before this payout method can be made available.Origination of funds is allowed only from a set of countries as mentioned in the table below.In case the transaction currency does not match the destination card issuer currency, amount will be converted and credited in currency of the card issuer.In few countries, only few banks may allow the transactions.Below additional daily/monthly/yearly limits applicable for P2P transactions whichever reached first Per Day - 30 transactions or USD 10,000 per Beneficiary card Per Week - 50 transactions or USD 25,000 per Beneficiary card Per Month - 150 transactions or USD 50,000 per Beneficiary card.Below additional daily/monthly/yearly limits applicable for B2P/B2B transactions whichever reached first Per Day - 30 transactions or USD 50,000 per Beneficiary card Per Week - 50 transactions or USD 100,000 per Beneficiary card Per Month - 150 transactions or USD 200,000 per Beneficiary card. | P12: 0 | Q12: 0 | R12: 0 | S12: 0 | T12: USD 50,000 | U12: USD 50,000 | V12: USD 2,500 | W12: USD 50,000
A13: Angola | B13: Foreign Currency Wire Transfer (SWIFT) | C13: USD, EUR, SGD, GBP, AUD, CAD, HKD, JPY, CHF, NZD | D13: T1 | E13: B2B, B2P, P2P, P2B | F13: B2B, B2P, P2P, P2B | G13: USD, EUR, SGD, GBP, AUD, CAD, HKD, JPY, CHF, NZD | H13: Bank | I13: All SWIFT enabled banks in the country | J13: Same-day processing subject to cutoff of 07:30 UTC | K13: Remitter Name, Remitter Account Type, Remitter Identification Type, Remitter Identification Number, Remitter Address, Remitter Country Code, Beneficiary Name, Beneficiary Account Type, Beneficiary Account Number, Beneficiary Country Code, Beneficiary Address (Recommended), Beneficiary City (Recommended), Beneficiary Postcode (Recommended), Routing Code Value 1, Routing Code Type 1 - SWIFT Code, Remit Purpose Code | L13: Remitter Beneficiary Relationship, Nature of Business, Duration of Contract, Commercial Agreement, Current Invoice | M13: Ultimate Sender Name and narrative details will be passed as part of MT103 message to beneficiary bank.Details available on beneficiary statement will be dependent on beneficiary bank. | N13: MT103 can be considered as a proof of payment and can be provided on request | O13: WIRES can be sent to all countries except for OFAC listed.MT103 can be provided on request.For foreign currency wire currencies USD, EUR, GBP - NIUM supports both OUR and SHA fee type while for other currencies AUD, CAD, CHF, JPY, NZD, HKD, SGD - NIUM supports only SHA fee typeProcessing of payments to Crimea, Donetsk, Luhansk, Sevastopol regions of Ukraine is prohibited. This list is subject to change. | P13: 0 | Q13: 0 | R13: 0 | S13: 0 | T13: No limit | U13: No limit | V13: No limit | W13: No limit
A14: Angola | B14: Visa Direct | C14: AOA | D14: T2 | E14: B2B, B2P, P2P, P2B | F14: B2B, B2P, P2P, P2B | G14: AOA | H14: VISA | J14: 1. 24x7 Availability2. Real-time for Fast fund Enabled (Details on fast-fund enabled countries available on request)3. T+2 for other countries | K14: Remitter Name, Remitter Identification Type, Remitter Identification Number, Remitter Country Code, Beneficiary Card Number, Beneficiary Name, Beneficiary Country Code | O14: For more information, please contact your NIUM account manager team. Additional information and approval from VISA is required before this payout method can be made available.Origination of funds is allowed only from a set of countries as mentioned in the table below.In case the transaction currency does not match the destination card issuer currency, amount will be converted and credited in currency of the card issuer.In few countries, only few banks may allow the transactions.Below additional daily/monthly/yearly limits applicable for P2P transactions whichever reached first Per Day - 30 transactions or USD 10,000 per Beneficiary card Per Week - 50 transactions or USD 25,000 per Beneficiary card Per Month - 150 transactions or USD 50,000 per Beneficiary card.Below additional daily/monthly/yearly limits applicable for B2P/B2B transactions whichever reached first Per Day - 30 transactions or USD 50,000 per Beneficiary card Per Week - 50 transactions or USD 100,000 per Beneficiary card Per Month - 150 transactions or USD 200,000 per Beneficiary card. | P14: 0 | Q14: 0 | R14: 0 | S14: 0 | T14: USD 50,000 | U14: USD 50,000 | V14: USD 2,500 | W14: USD 50,000
A15: Anguilla | B15: Foreign Currency Wire Transfer (SWIFT) | C15: USD, EUR, SGD, GBP, AUD, CAD, HKD, JPY, CHF, NZD | D15: T1 | E15: B2B, B2P, P2P, P2B | F15: B2B, B2P, P2P, P2B | G15: USD, EUR, SGD, GBP, AUD, CAD, HKD, JPY, CHF, NZD | H15: Bank | I15: All SWIFT enabled banks in the country | J15: Same-day processing subject to cutoff of 07:30 UTC | K15: Remitter Name, Remitter Account Type, Remitter Identification Type, Remitter Identification Number, Remitter Address, Remitter Country Code, Beneficiary Name, Beneficiary Account Type, Beneficiary Account Number, Beneficiary Country Code, Beneficiary Address, Beneficiary City, Beneficiary Postcode, Routing Code Value 1, Routing Code Type 1 - SWIFT Code, Remit Purpose Code | L15: Remitter Beneficiary Relationship, Nature of Business, Duration of Contract, Commercial Agreement, Current Invoice | M15: Ultimate Sender Name and narrative details will be passed as part of MT103 message to beneficiary bank.Details available on beneficiary statement will be dependent on beneficiary bank. | N15: MT103 can be considered as a proof of payment and can be provided on request | O15: WIRES can be sent to all countries except for OFAC listed.MT103 can be provided on request.NIUM does not support OUR charge type for CAD currency WIRESProcessing of payments to Crimea, Donetsk, Luhansk, Sevastopol regions of Ukraine is prohibited. This list is subject to change. | P15: 0 | Q15: 0 | R15: 0 | S15: 0 | T15: No limit | U15: No limit | V15: No limit | W15: No limit
A16: Antarctica | B16: Foreign Currency Wire Transfer (SWIFT) | C16: USD, EUR, SGD, GBP, AUD, CAD, HKD, JPY, CHF, NZD | D16: T1 | E16: B2B, B2P, P2P, P2B | F16: B2B, B2P, P2P, P2B | G16: USD, EUR, SGD, GBP, AUD, CAD, HKD, JPY, CHF, NZD | H16: Bank | I16: All SWIFT enabled banks in the country | J16: Same-day processing subject to cutoff of 07:30 UTC | K16: Remitter Name, Remitter Account Type, Remitter Identification Type, Remitter Identification Number, Remitter Address, Remitter Country Code, Beneficiary Name, Beneficiary Account Type, Beneficiary Account Number, Beneficiary Country Code, Beneficiary Address, Beneficiary City, Beneficiary Postcode, Routing Code Value 1, Routing Code Type 1 - SWIFT Code, Remit Purpose Code | L16: Remitter Beneficiary Relationship, Nature of Business, Duration of Contract, Commercial Agreement, Current Invoice | M16: Ultimate Sender Name and narrative details will be passed as part of MT103 message to beneficiary bank.Details available on beneficiary statement will be dependent on beneficiary bank. | N16: MT103 can be considered as a proof of payment and can be provided on request | O16: WIRES can be sent to all countries except for OFAC listed.MT103 can be provided on request.NIUM does not support OUR charge type for CAD currency WIRESProcessing of payments to Crimea, Donetsk, Luhansk, Sevastopol regions of Ukraine is prohibited. This list is subject to change. | P16: 0 | Q16: 0 | R16: 0 | S16: 0 | T16: No limit | U16: No limit | V16: No limit | W16: No limit
A17: Antigua | B17: Foreign Currency Wire Transfer (SWIFT) | C17: USD, EUR, SGD, GBP, AUD, CAD, HKD, JPY, CHF, NZD | D17: T1 | E17: B2B, B2P, P2P, P2B | F17: B2B, B2P, P2P, P2B | G17: USD, EUR, SGD, GBP, AUD, CAD, HKD, JPY, CHF, NZD | H17: Bank | I17: All SWIFT enabled banks in the country | J17: Same-day processing subject to cutoff of 07:30 UTC | K17: Remitter Name, Remitter Account Type, Remitter Identification Type, Remitter Identification Number, Remitter Address, Remitter Country Code, Beneficiary Name, Beneficiary Account Type, Beneficiary Account Number, Beneficiary Country Code, Beneficiary Address, Beneficiary City, Beneficiary Postcode, Routing Code Value 1, Routing Code Type 1 - SWIFT Code, Remit Purpose Code | L17: Remitter Beneficiary Relationship, Nature of Business, Duration of Contract, Commercial Agreement, Current Invoice | M17: Ultimate Sender Name and narrative details will be passed as part of MT103 message to beneficiary bank.Details available on beneficiary statement will be dependent on beneficiary bank. | N17: MT103 can be considered as a proof of payment and can be provided on request | O17: WIRES can be sent to all countries except for OFAC listed.MT103 can be provided on request.NIUM does not support OUR charge type for CAD currency WIRESProcessing of payments to Crimea, Donetsk, Luhansk, Sevastopol regions of Ukraine is prohibited. This list is subject to change. | P17: 0 | Q17: 0 | R17: 0 | S17: 0 | T17: No limit | U17: No limit | V17: No limit | W17: No limit
A18: Argentina | B18: Bank Account (ACH) | C18: ARS | D18: Realtime | E18: B2B, B2P, P2P, P2B | F18: B2B, B2P, P2P, P2B | G18: ARS | H18: Partner | I18: All banks in Argentina | J18: REALTIME, 24x7 | K18: Remitter Name, Remitter Identification Type, Remitter Address, Beneficiary Name, Beneficiary Country Code, Beneficiary Account Number, Beneficiary Identification Value, Remitter Account Type, Remitter Identification Number, Remitter Country Code, Beneficiary Account Type, Beneficiary Identification Type, Remit Purpose Code | L18: Remitter Beneficiary Relationship, Nature of Business, Duration of Contract, Commercial Agreement, Current Invoice | M18: Domestic Clearing System limits ability to transfer full remitter information to the Beneficiary. Visibility of Standard Statement Narration is missing | P18: 0 | Q18: 0 | R18: 0 | S18: 0 | T18: No limit | U18: No limit | V18: No limit | W18: No limit
A19: Argentina | B19: Foreign Currency Wire Transfer (SWIFT) | C19: USD, EUR, SGD, GBP, AUD, CAD, HKD, JPY, CHF, NZD | D19: T1 | E19: B2B, B2P, P2P, P2B | F19: B2B, B2P, P2P, P2B | G19: USD, EUR, SGD, GBP, AUD, CAD, HKD, JPY, CHF, NZD | H19: Bank | I19: All SWIFT enabled banks in the country | J19: Same-day processing subject to cutoff of 07:30 UTC | K19: Remitter Name, Remitter Account Type, Remitter Identification Type, Remitter Identification Number, Remitter Address, Remitter Country Code, Beneficiary Name, Beneficiary Account Type, Beneficiary Account Number, Beneficiary Country Code, Beneficiary Address, Beneficiary City, Beneficiary Postcode, Routing Code Value 1, Routing Code Type 1 - SWIFT Code, Remit Purpose Code | L19: Remitter Beneficiary Relationship, Nature of Business, Duration of Contract, Commercial Agreement, Current Invoice | M19: Ultimate Sender Name and narrative details will be passed as part of MT103 message to beneficiary bank.Details available on beneficiary statement will be dependent on beneficiary bank. | N19: MT103 can be considered as a proof of payment and can be provided on request | O19: WIRES can be sent to all countries except for OFAC listed.MT103 can be provided on request.NIUM does not support OUR charge type for CAD currency WIRESProcessing of payments to Crimea, Donetsk, Luhansk, Sevastopol regions of Ukraine is prohibited. This list is subject to change. | P19: 0 | Q19: 0 | R19: 0 | S19: 0 | T19: No limit | U19: No limit | V19: No limit | W19: No limit
A20: Armenia | B20: Foreign Currency Wire Transfer (SWIFT) | C20: USD, EUR, SGD, GBP, AUD, CAD, HKD, JPY, CHF, NZD | D20: T1 | E20: B2B, B2P, P2P, P2B | F20: B2B, B2P, P2P, P2B | G20: USD, EUR, SGD, GBP, AUD, CAD, HKD, JPY, CHF, NZD | H20: Bank | I20: All SWIFT enabled banks in the country | J20: Same-day processing subject to cutoff of 07:30 UTC | K20: Remitter Name, Remitter Account Type, Remitter Identification Type, Remitter Identification Number, Remitter Address, Remitter Country Code, Beneficiary Name, Beneficiary Account Type, Beneficiary Account Number, Beneficiary Country Code, Beneficiary Address (Recommended), Beneficiary City (Recommended), Beneficiary Postcode (Recommended), Routing Code Value 1, Routing Code Type 1 - SWIFT Code, Remit Purpose Code | L20: Remitter Beneficiary Relationship, Nature of Business, Duration of Contract, Commercial Agreement, Current Invoice | M20: Ultimate Sender Name and narrative details will be passed as part of MT103 message to beneficiary bank.Details available on beneficiary statement will be dependent on beneficiary bank. | N20: MT103 can be considered as a proof of payment and can be provided on request | O20: WIRES can be sent to all countries except for OFAC listed.MT103 can be provided on request.For foreign currency wire currencies USD, EUR, GBP - NIUM supports both OUR and SHA fee type while for other currencies AUD, CAD, CHF, JPY, NZD, HKD, SGD - NIUM supports only SHA fee typeProcessing of payments to Crimea, Donetsk, Luhansk, Sevastopol regions of Ukraine is prohibited. This list is subject to change. | P20: 0 | Q20: 0 | R20: 0 | S20: 0 | T20: No limit | U20: No limit | V20: No limit | W20: No limit
A21: Armenia | B21: Visa Direct | C21: AMD | D21: Realtime | E21: B2B, B2P, P2P, P2B | F21: B2B, B2P, P2P, P2B | G21: AMD | H21: VISA | J21: 1. 24x7 Availability2. Real-time for Fast fund Enabled (Details on fast-fund enabled countries available on request)3. T+2 for other countries | K21: Remitter Name, Remitter Identification Type, Remitter Identification Number, Remitter Country Code, Beneficiary Card Number, Beneficiary Name, Beneficiary Country Code | O21: For more information, please contact your NIUM account manager team. Additional information and approval from VISA is required before this payout method can be made available.Origination of funds is allowed only from a set of countries as mentioned in the table below.In case the transaction currency does not match the destination card issuer currency, amount will be converted and credited in currency of the card issuer.In few countries, only few banks may allow the transactions.Below additional daily/monthly/yearly limits applicable for P2P transactions whichever reached first Per Day - 30 transactions or USD 10,000 per Beneficiary card Per Week - 50 transactions or USD 25,000 per Beneficiary card Per Month - 150 transactions or USD 50,000 per Beneficiary card.Below additional daily/monthly/yearly limits applicable for B2P/B2B transactions whichever reached first Per Day - 30 transactions or USD 50,000 per Beneficiary card Per Week - 50 transactions or USD 100,000 per Beneficiary card Per Month - 150 transactions or USD 200,000 per Beneficiary card. | P21: 0 | Q21: 0 | R21: 0 | S21: 0 | T21: USD 50,000 | U21: USD 50,000 | V21: USD 2,500 | W21: USD 50,000
A22: Aruba | B22: Foreign Currency Wire Transfer (SWIFT) | C22: USD, EUR, SGD, GBP, AUD, CAD, HKD, JPY, CHF, NZD | D22: T1 | E22: B2B, B2P, P2P, P2B | F22: B2B, B2P, P2P, P2B | G22: USD, EUR, SGD, GBP, AUD, CAD, HKD, JPY, CHF, NZD | H22: Bank | I22: All SWIFT enabled banks in the country | J22: Same-day processing subject to cutoff of 07:30 UTC | K22: Remitter Name, Remitter Account Type, Remitter Identification Type, Remitter Identification Number, Remitter Address, Remitter Country Code, Beneficiary Name, Beneficiary Account Type, Beneficiary Account Number, Beneficiary Country Code, Beneficiary Address, Beneficiary City, Beneficiary Postcode, Routing Code Value 1, Routing Code Type 1 - SWIFT Code, Remit Purpose Code | L22: Remitter Beneficiary Relationship, Nature of Business, Duration of Contract, Commercial Agreement, Current Invoice | M22: Ultimate Sender Name and narrative details will be passed as part of MT103 message to beneficiary bank.Details available on beneficiary statement will be dependent on beneficiary bank. | N22: MT103 can be considered as a proof of payment and can be provided on request | O22: WIRES can be sent to all countries except for OFAC listed.MT103 can be provided on request.NIUM does not support OUR charge type for CAD currency WIRESProcessing of payments to Crimea, Donetsk, Luhansk, Sevastopol regions of Ukraine is prohibited. This list is subject to change. | P22: 0 | Q22: 0 | R22: 0 | S22: 0 | T22: No limit | U22: No limit | V22: No limit | W22: No limit
A23: Australia | B23: Bank Account (ACH) | C23: AUD | D23: Realtime | E23: B2B, B2P, P2P, P2B | F23: B2B, B2P, P2P, P2B | G23: AUD | H23: Bank | I23: All banks in Australia | J23: Realtime 24x7 for domestic AUD transactions through NPPSame-day credit subject window 08:30 to 19:00 AEST from Monday to Friday | K23: Remitter Name, Remitter Account Type, Remitter Country Code, Remitter Address, Remitter Identification Type, Remitter Identification Number, Beneficiary Name, Beneficiary Country Code, Beneficiary Account Type, Beneficiary Address, Beneficiary City, Beneficiary Account Number, Beneficiary Contact No, Beneficiary Post Code, Routing Code Type 1 - BSB Code, Routing Code Value 1 | L23: Remitter Beneficiary Relationship, Nature of Business, Duration of Contract, Commercial Agreement, Current Invoice | M23: Remitter name and Statement narrative provided by the customer will be visible in the Beneficiary's Statement. | P23: AUD 0.01 | Q23: AUD 0.01 | R23: AUD 0.01 | S23: AUD 0.01 | T23: No limit | U23: No limit | V23: No limit | W23: No limit
A24: Australia | B24: Foreign Currency Wire Transfer (SWIFT) | C24: USD, EUR, SGD, GBP, AUD, CAD, HKD, JPY, CHF, NZD | D24: T1 | E24: B2B, B2P, P2P, P2B | F24: B2B, B2P, P2P, P2B | G24: USD, EUR, SGD, GBP, AUD, CAD, HKD, JPY, CHF, NZD | H24: Bank | I24: All SWIFT enabled banks in the country | J24: Same-day processing subject to cutoff of 07:30 UTC | K24: Remitter Name, Remitter Account Type, Remitter Identification Type, Remitter Identification Number, Remitter Address, Remitter Country Code, Beneficiary Name, Beneficiary Account Type, Beneficiary Account Number, Beneficiary Country Code, Beneficiary Address, Beneficiary City, Beneficiary Postcode, Routing Code Value 1, Routing Code Type 1 - SWIFT Code, Remit Purpose Code | L24: Remitter Beneficiary Relationship, Nature of Business, Duration of Contract, Commercial Agreement, Current Invoice | M24: Ultimate Sender Name and narrative details will be passed as part of MT103 message to beneficiary bank.Details available on beneficiary statement will be dependent on beneficiary bank. | N24: MT103 can be considered as a proof of payment and can be provided on request | O24: WIRES can be sent to all countries except for OFAC listed.MT103 can be provided on request.NIUM does not support OUR charge type for CAD currency WIRESProcessing of payments to Crimea, Donetsk, Luhansk, Sevastopol regions of Ukraine is prohibited. This list is subject to change. | P24: 0 | Q24: 0 | R24: 0 | S24: 0 | T24: No limit | U24: No limit | V24: No limit | W24: No limit
A25: Australia | B25: Proxy (Bank account) | C25: AUD | D25: Realtime | E25: B2B, B2P, P2P, P2B | F25: B2B, B2P, P2P, P2B | G25: AUD | H25: Bank | I25: All NPP enabled Banks | J25: PayID, Real Time - 24x7 | K25: Remitter Name, Remitter Account Type, Remitter Country Code, Remitter Address, Remitter Identification Type, Remitter Identification Number, Beneficiary Name, Beneficiary Country Code, Beneficiary Account Type, Proxy Type, Proxy Value | L25: Remitter Beneficiary Relationship, Nature of Business, Duration of Contract, Commercial Agreement, Current Invoice | M25: Reference number will be visible in the Beneficiary"s bank statement. | O25: Value for proxy type should be a. ABN b. EMAIL c. PHONE NUMBER d. CORPORATE ID | P25: 0 | Q25: 0 | R25: 0 | S25: 0 | T25: No limit | U25: No limit | V25: No limit | W25: No limit | X25: Can verify both the proxy value and the proxy holder's name.
A26: Austria | B26: Bank Account (SEPA) | C26: EUR | D26: Realtime | E26: B2B, B2P, P2P, P2B | F26: B2B, B2P, P2P, P2B | G26: EUR | H26: Bank | I26: All banks connected with SEPA Network | J26: 1. Real-time for transaction amount <= EUR 100,0002. Same-day for transaction amount > EUR 100,000 subject to cutoff of 14.00 EET | K26: Remitter Name, Remitter Account Type, Remitter Address, Remitter Country Code, Remitter Identification Type, Remitter Identification Number, Remit Purpose Code, Remitter City, Remitter Postcode, Beneficiary Name, Beneficiary Country Code, Beneficiary Account Type, Beneficiary Account Number - IBAN, Routing Code Type 1 - SWIFT CODE, Routing Code Value 1 | L26: Remitter Beneficiary Relationship, Nature of Business, Duration of Contract, Commercial Agreement, Current Invoice | M26: Remitter Name & NIUM appears in the beneficiary statement | N26: Upon request, Proof of Payment for a transaction can be made available. | O26: 1. Coverage includes the EU as well as several Non-EU countries.2. Not all supported countries support Realtime payments3. Few banks in Instant supported countries may not support instant payments and payments will be routed through Standard mode in such cases.4.Certain banks require the complete 11-character SWIFT codeâ€”including the branch identifierâ€”in order to accurately route and successfully process the payment. | P26: EUR 0.01 | Q26: EUR 0.01 | R26: EUR 0.01 | S26: EUR 0.01 | T26: No limit | U26: No limit | V26: No limit | W26: No limit
A27: Austria | B27: Foreign Currency Wire Transfer (SWIFT) | C27: USD, EUR, SGD, GBP, AUD, CAD, HKD, JPY, CHF, NZD | D27: T1 | E27: B2B, B2P, P2P, P2B | F27: B2B, B2P, P2P, P2B | G27: USD, EUR, SGD, GBP, AUD, CAD, HKD, JPY, CHF, NZD | H27: Bank | I27: All SWIFT enabled banks in the country | J27: Same-day processing subject to cutoff of 07:30 UTC | K27: Remitter Name, Remitter Account Type, Remitter Identification Type, Remitter Identification Number, Remitter Address, Remitter Country Code, Beneficiary Name, Beneficiary Account Type, Beneficiary Account Number, Beneficiary Country Code, Beneficiary Address, Beneficiary City, Beneficiary Postcode, Routing Code Value 1, Routing Code Type 1 - SWIFT Code, Remit Purpose Code | L27: Remitter Beneficiary Relationship, Nature of Business, Duration of Contract, Commercial Agreement, Current Invoice | M27: Ultimate Sender Name and narrative details will be passed as part of MT103 message to beneficiary bank. Details available on beneficiary statement will be dependent on beneficiary bank. | N27: MT103 can be considered as a proof of payment and can be provided on request | O27: WIRES can be sent to all countries except for OFAC listed.MT103 can be provided on request.NIUM does not support OUR charge type for CAD currency WIRESProcessing of payments to Crimea, Donetsk, Luhansk, Sevastopol regions of Ukraine is prohibited. This list is subject to change. | P27: 0 | Q27: 0 | R27: 0 | S27: 0 | T27: No limit | U27: No limit | V27: No limit | W27: No limit
A28: Austria | B28: Visa Direct | C28: EUR | D28: T2 | E28: B2B, B2P, P2P, P2B | F28: B2B, B2P, P2P, P2B | G28: EUR | H28: VISA | J28: 1. 24x7 Availability2. Real-time for Fast fund Enabled (Details on fast-fund enabled countries available on request)3. T+2 for other countries | K28: Remitter Name, Remitter Identification Type, Remitter Identification Number, Remitter Country Code, Beneficiary Card Number, Beneficiary Name, Beneficiary Country Code | O28: For more information, please contact your NIUM account manager team. Additional information and approval from VISA is required before this payout method can be made available.Origination of funds is allowed only from a set of countries as mentioned in the table below.In case the transaction currency does not match the destination card issuer currency, amount will be converted and credited in currency of the card issuer.In few countries, only few banks may allow the transactions.Below additional daily/monthly/yearly limits applicable for P2P transactions whichever reached first Per Day - 30 transactions or USD 10,000 per Beneficiary card Per Week - 50 transactions or USD 25,000 per Beneficiary card Per Month - 150 transactions or USD 50,000 per Beneficiary card.Below additional daily/monthly/yearly limits applicable for B2P/B2B transactions whichever reached first Per Day - 30 transactions or USD 50,000 per Beneficiary card Per Week - 50 transactions or USD 100,000 per Beneficiary card Per Month - 150 transactions or USD 200,000 per Beneficiary card. | P28: 0 | Q28: 0 | R28: 0 | S28: 0 | T28: USD 50,000 | U28: USD 50,000 | V28: USD 2,500 | W28: USD 50,000
A29: Azerbaijan | B29: Foreign Currency Wire Transfer (SWIFT) | C29: USD, EUR, SGD, GBP, AUD, CAD, HKD, JPY, CHF, NZD | D29: T1 | E29: B2B, B2P, P2P, P2B | F29: B2B, B2P, P2P, P2B | G29: USD, EUR, SGD, GBP, AUD, CAD, HKD, JPY, CHF, NZD | H29: Bank | I29: All SWIFT enabled banks in the country | J29: Same-day processing subject to cutoff of 07:30 UTC | K29: Remitter Name, Remitter Account Type, Remitter Identification Type, Remitter Identification Number, Remitter Address, Remitter Country Code, Beneficiary Name, Beneficiary Account Type, Beneficiary Account Number, Beneficiary Country Code, Beneficiary Address (Recommended), Beneficiary City (Recommended), Beneficiary Postcode (Recommended), Routing Code Value 1, Routing Code Type 1 - SWIFT Code, Remit Purpose Code | L29: Remitter Beneficiary Relationship, Nature of Business, Duration of Contract, Commercial Agreement, Current Invoice | M29: Ultimate Sender Name and narrative details will be passed as part of MT103 message to beneficiary bank.Details available on beneficiary statement will be dependent on beneficiary bank. | N29: MT103 can be considered as a proof of payment and can be provided on request | O29: WIRES can be sent to all countries except for OFAC listed.MT103 can be provided on request.For foreign currency wire currencies USD, EUR, GBP - NIUM supports both OUR and SHA fee type while for other currencies AUD, CAD, CHF, JPY, NZD, HKD, SGD - NIUM supports only SHA fee typeProcessing of payments to Crimea, Donetsk, Luhansk, Sevastopol regions of Ukraine is prohibited. This list is subject to change. | P29: 0 | Q29: 0 | R29: 0 | S29: 0 | T29: No limit | U29: No limit | V29: No limit | W29: No limit
A30: Azerbaijan | B30: Visa Direct | C30: AZN | D30: Realtime | E30: B2B, B2P, P2P, P2B | F30: B2B, B2P, P2P, P2B | G30: AZN | H30: VISA | J30: 1. 24x7 Availability2. Real-time for Fast fund Enabled (Details on fast-fund enabled countries available on request)3. T+2 for other countries | K30: Remitter Name, Remitter Identification Type, Remitter Identification Number, Remitter Country Code, Beneficiary Card Number, Beneficiary Name, Beneficiary Country Code | O30: For more information, please contact your NIUM account manager team. Additional information and approval from VISA is required before this payout method can be made available.Origination of funds is allowed only from a set of countries as mentioned in the table below.In case the transaction currency does not match the destination card issuer currency, amount will be converted and credited in currency of the card issuer.In few countries, only few banks may allow the transactions.Below additional daily/monthly/yearly limits applicable for P2P transactions whichever reached first Per Day - 30 transactions or USD 10,000 per Beneficiary card Per Week - 50 transactions or USD 25,000 per Beneficiary card Per Month - 150 transactions or USD 50,000 per Beneficiary card.Below additional daily/monthly/yearly limits applicable for B2P/B2B transactions whichever reached first Per Day - 30 transactions or USD 50,000 per Beneficiary card Per Week - 50 transactions or USD 100,000 per Beneficiary card Per Month - 150 transactions or USD 200,000 per Beneficiary card. | P30: 0 | Q30: 0 | R30: 0 | S30: 0 | T30: USD 50,000 | U30: USD 50,000 | V30: USD 2,500 | W30: USD 50,000
A31: Bahamas | B31: Foreign Currency Wire Transfer (SWIFT) | C31: USD, EUR, SGD, GBP, AUD, CAD, HKD, JPY, CHF, NZD | D31: T1 | E31: B2B, B2P, P2P, P2B | F31: B2B, B2P, P2P, P2B | G31: USD, EUR, SGD, GBP, AUD, CAD, HKD, JPY, CHF, NZD | H31: Bank | I31: All SWIFT enabled banks in the country | J31: Same-day processing subject to cutoff of 07:30 UTC | K31: Remitter Name, Remitter Account Type, Remitter Identification Type, Remitter Identification Number, Remitter Address, Remitter Country Code, Beneficiary Name, Beneficiary Account Type, Beneficiary Account Number, Beneficiary Country Code, Beneficiary Address, Beneficiary City, Beneficiary Postcode, Routing Code Value 1, Routing Code Type 1 - SWIFT Code, Remit Purpose Code | L31: Remitter Beneficiary Relationship, Nature of Business, Duration of Contract, Commercial Agreement, Current Invoice | M31: Ultimate Sender Name and narrative details will be passed as part of MT103 message to beneficiary bank.Details available on beneficiary statement will be dependent on beneficiary bank. | N31: MT103 can be considered as a proof of payment and can be provided on request | O31: WIRES can be sent to all countries except for OFAC listed.MT103 can be provided on request.NIUM does not support OUR charge type for CAD currency WIRESProcessing of payments to Crimea, Donetsk, Luhansk, Sevastopol regions of Ukraine is prohibited. This list is subject to change. | P31: 0 | Q31: 0 | R31: 0 | S31: 0 | T31: No limit | U31: No limit | V31: No limit | W31: No limit
A32: Bahamas | B32: Visa Direct | C32: BSD | D32: T2 | E32: B2B, B2P, P2P, P2B | F32: B2B, B2P, P2P, P2B | G32: BSD | H32: VISA | J32: 1. 24x7 Availability2. Real-time for Fast fund Enabled (Details on fast-fund enabled countries available on request)3. T+2 for other countries | K32: Remitter Name, Remitter Identification Type, Remitter Identification Number, Remitter Country Code, Beneficiary Card Number, Beneficiary Name, Beneficiary Country Code | O32: For more information, please contact your NIUM account manager team. Additional information and approval from VISA is required before this payout method can be made available.Origination of funds is allowed only from a set of countries as mentioned in the table below.In case the transaction currency does not match the destination card issuer currency, amount will be converted and credited in currency of the card issuer.In few countries, only few banks may allow the transactions.Below additional daily/monthly/yearly limits applicable for P2P transactions whichever reached first Per Day - 30 transactions or USD 10,000 per Beneficiary card Per Week - 50 transactions or USD 25,000 per Beneficiary card Per Month - 150 transactions or USD 50,000 per Beneficiary card.Below additional daily/monthly/yearly limits applicable for B2P/B2B transactions whichever reached first Per Day - 30 transactions or USD 50,000 per Beneficiary card Per Week - 50 transactions or USD 100,000 per Beneficiary card Per Month - 150 transactions or USD 200,000 per Beneficiary card. | P32: 0 | Q32: 0 | R32: 0 | S32: 0 | T32: USD 50,000 | U32: USD 50,000 | V32: USD 2,500 | W32: USD 50,000
A33: Bahrain | B33: Foreign Currency Wire Transfer (SWIFT) | C33: USD, EUR, SGD, GBP, AUD, CAD, HKD, JPY, CHF, NZD | D33: T1 | E33: B2B, B2P, P2P, P2B | F33: B2B, B2P, P2P, P2B | G33: USD, EUR, SGD, GBP, AUD, CAD, HKD, JPY, CHF, NZD | H33: Bank | I33: All SWIFT enabled banks in the country | J33: Same-day processing subject to cutoff of 07:30 UTC | K33: Remitter Name, Remitter Account Type, Remitter Identification Type, Remitter Identification Number, Remitter Address, Remitter Country Code, Beneficiary Name, Beneficiary Account Type, Beneficiary Account Number, Beneficiary Country Code, Beneficiary Address, Beneficiary City, Beneficiary Postcode, Routing Code Value 1, Routing Code Type 1 - SWIFT Code, Remit Purpose Code | L33: Remitter Beneficiary Relationship, Nature of Business, Duration of Contract, Commercial Agreement, Current Invoice | M33: Ultimate Sender Name and narrative details will be passed as part of MT103 message to beneficiary bank.Details available on beneficiary statement will be dependent on beneficiary bank. | N33: MT103 can be considered as a proof of payment and can be provided on request | O33: WIRES can be sent to all countries except for OFAC listed.MT103 can be provided on request.NIUM does not support OUR charge type for CAD currency WIRESProcessing of payments to Crimea, Donetsk, Luhansk, Sevastopol regions of Ukraine is prohibited. This list is subject to change. | P33: 0 | Q33: 0 | R33: 0 | S33: 0 | T33: No limit | U33: No limit | V33: No limit | W33: No limit
A34: Bahrain | B34: Visa Direct | C34: BHD | D34: T2 | E34: B2B, B2P, P2P, P2B | F34: B2B, B2P, P2P, P2B | G34: BHD | H34: VISA | J34: 1. 24x7 Availability2. Real-time for Fast fund Enabled (Details on fast-fund enabled countries available on request)3. T+2 for other countries | K34: Remitter Name, Remitter Identification Type, Remitter Identification Number, Remitter Country Code, Beneficiary Card Number, Beneficiary Name, Beneficiary Country Code | O34: For more information, please contact your NIUM account manager team. Additional information and approval from VISA is required before this payout method can be made available.Origination of funds is allowed only from a set of countries as mentioned in the table below.In case the transaction currency does not match the destination card issuer currency, amount will be converted and credited in currency of the card issuer.In few countries, only few banks may allow the transactions.Below additional daily/monthly/yearly limits applicable for P2P transactions whichever reached first Per Day - 30 transactions or USD 10,000 per Beneficiary card Per Week - 50 transactions or USD 25,000 per Beneficiary card Per Month - 150 transactions or USD 50,000 per Beneficiary card.Below additional daily/monthly/yearly limits applicable for B2P/B2B transactions whichever reached first Per Day - 30 transactions or USD 50,000 per Beneficiary card Per Week - 50 transactions or USD 100,000 per Beneficiary card Per Month - 150 transactions or USD 200,000 per Beneficiary card. | P34: 0 | Q34: 0 | R34: 0 | S34: 0 | T34: USD 50,000 | U34: USD 50,000 | V34: USD 2,500 | W34: USD 50,000
A35: Bailiwick of Guernsey | B35: Bank Account (ACH) | C35: GBP | D35: Realtime | E35: B2B, B2P, P2P, P2B | F35: B2B, B2P, P2P, P2B | G35: GBP | H35: Bank | I35: All banks in UK | J35: 1. Real-time for transaction amount <= GBP 1 Mn2. Same day for transaction amount > GBP 1 Mn subject to cut-off of 15.30 GMT only on working days | K35: Remitter Name, Remitter Account Type, Remitter Address, Remitter Country Code, Remitter Identification Type, Remitter Identificiation Value, Remit Purpose Code, Beneficiary Name, Beneficiary Account Number, Beneficiary Country Code, Beneficiary Account Type, Routing Code Type 1 - Sort Code, Routing Code Value 1 | L35: Remitter Beneficiary Relationship, Nature of Business, Duration of Contract, Commercial Agreement, Current Invoice | M35: NIUM Fintech & Statement Narrative will be visible in the Beneficiarys Bank statement. | O35: The beneficiary account number may be provided in either IBAN or basic account number format. If an IBAN is used, the sort code is typically not required. However, certain banks specifically require an 8-digit account number format to successfully process payments. | P35: GBP 1 | Q35: GBP 1 | R35: GBP 1 | S35: GBP 1 | T35: No limit | U35: No limit | V35: No limit | W35: No limit
A36: Bailiwick of Guernsey | B36: Bank Account (SEPA) | C36: EUR | D36: Realtime | E36: B2B, B2P, P2P, P2B | F36: B2B, B2P, P2P, P2B | G36: EUR | H36: Bank | I36: All banks connected with SEPA Network | J36: 1. Real-time for transaction amount <= EUR 100,0002. Same-day for transaction amount > EUR 100,000 subject to cutoff of 14.00 EET | K36: Remitter Name, Remitter Account Type, Remitter Address, Remitter Country Code, Remitter Identification Type, Remitter Identification Number, Remit Purpose Code, Remitter City, Remitter Postcode, Beneficiary Name, Beneficiary Country Code, Beneficiary Account Type, Beneficiary Account Number - IBAN, Routing Code Type 1 - SWIFT CODE, Routing Code Value 1 | L36: Remitter Beneficiary Relationship, Nature of Business, Duration of Contract, Commercial Agreement, Current Invoice | M36: Remitter Name & NIUM appears in the beneficiary statement | N36: Upon request, Proof of Payment for a transaction can be made available. | O36: 1. Coverage includes the EU as well as several Non-EU countries.2. Not all supported countries support Realtime payments3. Few banks in Instant supported countries may not support instant payments and payments will be routed through Standard mode in such cases.4.Certain banks require the complete 11-character SWIFT codeâ€”including the branch identifierâ€”in order to accurately route and successfully process the payment. | P36: EUR 0.01 | Q36: EUR 0.01 | R36: EUR 0.01 | S36: EUR 0.01 | T36: No limit | U36: No limit | V36: No limit | W36: No limit
A37: Bailiwick of Guernsey | B37: Foreign Currency Wire Transfer (SWIFT) | C37: USD, EUR, SGD, AUD, CAD, HKD, JPY, CHF, NZD | D37: T1 | E37: B2B, B2P, P2P, P2B | F37: B2B, B2P, P2P, P2B | G37: USD, EUR, SGD, AUD, CAD, HKD, JPY, CHF, NZD | H37: Bank | I37: All SWIFT enabled banks in the country | J37: Same-day processing subject to cutoff of 07:30 UTC | K37: Remitter Name, Remitter Account Type, Remitter Identification Type, Remitter Identification Number, Remitter Address, Remitter Country Code, Beneficiary Name, Beneficiary Account Type, Beneficiary Account Number, Beneficiary Country Code, Beneficiary Address (Recommended), Beneficiary City (Recommended), Beneficiary Postcode (Recommended), Routing Code Value 1, Routing Code Type 1 - SWIFT Code, Remit Purpose Code | L37: Remitter Beneficiary Relationship, Nature of Business, Duration of Contract, Commercial Agreement, Current Invoice | M37: Ultimate Sender Name and narrative details will be passed as part of MT103 message to beneficiary bank.Details available on beneficiary statement will be dependent on beneficiary bank. | N37: MT103 can be considered as a proof of payment and can be provided on request | O37: WIRES can be sent to all countries except for OFAC listed.MT103 can be provided on request.For foreign currency wire currencies USD, EUR, GBP - NIUM supports both OUR and SHA fee type while for other currencies AUD, CAD, CHF, JPY, NZD, HKD, SGD - NIUM supports only SHA fee typeProcessing of payments to Crimea, Donetsk, Luhansk, Sevastopol regions of Ukraine is prohibited. This list is subject to change. | P37: 0 | Q37: 0 | R37: 0 | S37: 0 | T37: No limit | U37: No limit | V37: No limit | W37: No limit
A38: Bangladesh | B38: Bank Account (ACH) | C38: BDT | D38: T0 | E38: P2P | F38: P2P | G38: BDT | H38: Bank | I38: All banks in Bangladesh | J38: 07:30 to 22:00 local time Sunday to Thursday | K38: Remitter Name, Remitter Identification Type, Remitter Address, Beneficiary Name, Beneficiary Account Number, Beneficiary Contact Number, Routing Code Value 1, Routing Code Value 2, Remitter Account Type, Remitter Identification Number, Remitter Country Code, Beneficiary Account Type, Routing Code Type 1 - SWIFT CODE, Routing Code Type 1 - BRANCH NAME, Beneficiary Address | L38: Remitter Beneficiary Relationship, Nature of Business, Duration of Contract, Commercial Agreement, Current Invoice | M38: Domestic Clearing System limits ability to transfer full remitter information to the Beneficiary. Visibility of Standard Statement Narration is missing. | P38: Not Supported | Q38: Not Supported | R38: BDT 1 | S38: Not Supported | T38: Not Supported | U38: Not Supported | V38: No limit | W38: Not Supported
A39: Bangladesh | B39: Foreign Currency Wire Transfer (SWIFT) | C39: USD, EUR, SGD, GBP, AUD, CAD, HKD, JPY, CHF, NZD | D39: T1 | E39: B2B, B2P, P2P, P2B | F39: B2B, B2P, P2P, P2B | G39: USD, EUR, SGD, GBP, AUD, CAD, HKD, JPY, CHF, NZD | H39: Bank | I39: All SWIFT enabled banks in the country | J39: Same-day processing subject to cutoff of 07:30 UTC | K39: Remitter Name, Remitter Account Type, Remitter Identification Type, Remitter Identification Number, Remitter Address, Remitter Country Code, Beneficiary Name, Beneficiary Account Type, Beneficiary Account Number, Beneficiary Country Code, Beneficiary Address, Beneficiary City, Beneficiary Postcode, Routing Code Value 1, Routing Code Type 1 - SWIFT Code, Remit Purpose Code | L39: Remitter Beneficiary Relationship, Nature of Business, Duration of Contract, Commercial Agreement, Current Invoice | M39: Ultimate Sender Name and narrative details will be passed as part of MT103 message to beneficiary bank.Details available on beneficiary statement will be dependent on beneficiary bank. | N39: MT103 can be considered as a proof of payment and can be provided on request | O39: WIRES can be sent to all countries except for OFAC listed.MT103 can be provided on request.NIUM does not support OUR charge type for CAD currency WIRESProcessing of payments to Crimea, Donetsk, Luhansk, Sevastopol regions of Ukraine is prohibited. This list is subject to change. | P39: 0 | Q39: 0 | R39: 0 | S39: 0 | T39: No limit | U39: No limit | V39: No limit | W39: No limit
A40: Bangladesh | B40: Visa Direct | C40: BDT | D40: Realtime | E40: B2B, B2P, P2P, P2B | F40: B2B, B2P, P2P, P2B | G40: BDT | H40: VISA | J40: 1. 24x7 Availability2. Real-time for Fast fund Enabled (Details on fast-fund enabled countries available on request)3. T+2 for other countries | K40: Remitter Name, Remitter Identification Type, Remitter Identification Number, Remitter Country Code, Beneficiary Card Number, Beneficiary Name, Beneficiary Country Code | O40: For more information, please contact your NIUM account manager team. Additional information and approval from VISA is required before this payout method can be made available.Origination of funds is allowed only from a set of countries as mentioned in the table below.In case the transaction currency does not match the destination card issuer currency, amount will be converted and credited in currency of the card issuer.In few countries, only few banks may allow the transactions.Below additional daily/monthly/yearly limits applicable for P2P transactions whichever reached first Per Day - 30 transactions or USD 10,000 per Beneficiary card Per Week - 50 transactions or USD 25,000 per Beneficiary card Per Month - 150 transactions or USD 50,000 per Beneficiary card.Below additional daily/monthly/yearly limits applicable for B2P/B2B transactions whichever reached first Per Day - 30 transactions or USD 50,000 per Beneficiary card Per Week - 50 transactions or USD 100,000 per Beneficiary card Per Month - 150 transactions or USD 200,000 per Beneficiary card. | P40: 0 | Q40: 0 | R40: 0 | S40: 0 | T40: USD 50,000 | U40: USD 50,000 | V40: USD 2,500 | W40: USD 50,000
...

Sheet Sheet2
A1: AED | B1: =VLOOKUP(A1,Sheet1!C:C,1,0) -> AED
A2: ARS | B2: =VLOOKUP(A2,Sheet1!C:C,1,0) -> ARS
A3: AUD | B3: =VLOOKUP(A3,Sheet1!C:C,1,0) -> AUD
A4: BGN | B4: =VLOOKUP(A4,Sheet1!C:C,1,0) -> BGN
A5: BRL | B5: =VLOOKUP(A5,Sheet1!C:C,1,0) -> BRL
A6: CAD | B6: =VLOOKUP(A6,Sheet1!C:C,1,0) -> CAD
A7: CHF | B7: =VLOOKUP(A7,Sheet1!C:C,1,0) -> #N/A
A8: CLP | B8: =VLOOKUP(A8,Sheet1!C:C,1,0) -> CLP
A9: CNY | B9: =VLOOKUP(A9,Sheet1!C:C,1,0) -> CNY
A10: COP | B10: =VLOOKUP(A10,Sheet1!C:C,1,0) -> COP
A11: CZK | B11: =VLOOKUP(A11,Sheet1!C:C,1,0) -> CZK
A12: DKK | B12: =VLOOKUP(A12,Sheet1!C:C,1,0) -> DKK
... A41: ZAR | B41: =VLOOKUP(A41,Sheet1!C:C,1,0) -> ZAR
